ERROR 2024-09-27 05:56:21,382 log Internal Server Error: /app/withdrawal/
Traceback (most recent call last):
  File "C:\Users\achod\OneDrive\Desktop\Archive\brokers\exchange-vista\vista\Lib\site-packages\django\core\handlers\exception.py", line 55, in inner
    response = get_response(request)
               ^^^^^^^^^^^^^^^^^^^^^
  File "C:\Users\achod\OneDrive\Desktop\Archive\brokers\exchange-vista\vista\Lib\site-packages\django\core\handlers\base.py", line 197, in _get_response
    response = wrapped_callback(request, *callback_args, **callback_kwargs)
               ^^^^^^^^^^^^^^^^^^^^^^^^^^^^^^^^^^^^^^^^^^^^^^^^^^^^^^^^^^^^
  File "C:\Users\achod\OneDrive\Desktop\Archive\brokers\exchange-vista\vista\Lib\site-packages\django\contrib\auth\decorators.py", line 23, in _wrapper_view
    return view_func(request, *args, **kwargs)
           ^^^^^^^^^^^^^^^^^^^^^^^^^^^^^^^^^^^
  File "C:\Users\achod\OneDrive\Desktop\Archive\brokers\exchange-vista\exchangevista\app\views.py", line 1224, in withdrawal
    amount = Decimal(amount)
             ^^^^^^^^^^^^^^^
decimal.InvalidOperation: [<class 'decimal.ConversionSyntax'>]
ERROR 2024-09-27 05:56:21,394 log Internal Server Error: /app/withdrawal/
Traceback (most recent call last):
  File "C:\Users\achod\OneDrive\Desktop\Archive\brokers\exchange-vista\vista\Lib\site-packages\django\core\handlers\exception.py", line 55, in inner
    response = get_response(request)
               ^^^^^^^^^^^^^^^^^^^^^
  File "C:\Users\achod\OneDrive\Desktop\Archive\brokers\exchange-vista\vista\Lib\site-packages\django\core\handlers\base.py", line 197, in _get_response
    response = wrapped_callback(request, *callback_args, **callback_kwargs)
               ^^^^^^^^^^^^^^^^^^^^^^^^^^^^^^^^^^^^^^^^^^^^^^^^^^^^^^^^^^^^
  File "C:\Users\achod\OneDrive\Desktop\Archive\brokers\exchange-vista\vista\Lib\site-packages\django\contrib\auth\decorators.py", line 23, in _wrapper_view
    return view_func(request, *args, **kwargs)
           ^^^^^^^^^^^^^^^^^^^^^^^^^^^^^^^^^^^
  File "C:\Users\achod\OneDrive\Desktop\Archive\brokers\exchange-vista\exchangevista\app\views.py", line 1224, in withdrawal
    amount = Decimal(amount)
             ^^^^^^^^^^^^^^^
decimal.InvalidOperation: [<class 'decimal.ConversionSyntax'>]
ERROR 2024-09-27 05:56:21,399 basehttp "POST /app/withdrawal/ HTTP/1.1" 500 79063
ERROR 2024-09-27 05:56:21,402 basehttp "POST /app/withdrawal/ HTTP/1.1" 500 79063
ERROR 2024-09-29 14:42:59,776 log Internal Server Error: /api/check_eligibility/1
ERROR 2024-09-29 14:42:59,778 basehttp "GET /api/check_eligibility/1 HTTP/1.1" 500 33
ERROR 2024-09-29 15:24:39,297 models Failed to send welcome email to support@exchangevista.com. Error: CustomUser has no profiles.
Traceback (most recent call last):
  File "C:\Users\achod\OneDrive\Desktop\Archive\brokers\exchange-vista\exchangevista\app\models.py", line 61, in send_new_user_email
    message=f"User: {instance.username} just created a new vista account. Please log in and review. here are some important information[ full name: {instance.firstname} {instance.lastname}. username: {instance.username}, country: {instance.profiles.nationality}. ]",
                                                                                                                                                                                                                                       ^^^^^^^^^^^^^^^^^
  File "C:\Users\achod\OneDrive\Desktop\Archive\brokers\exchange-vista\vista\Lib\site-packages\django\db\models\fields\related_descriptors.py", line 525, in __get__
    raise self.RelatedObjectDoesNotExist(
app.models.CustomUser.profiles.RelatedObjectDoesNotExist: CustomUser has no profiles.
ERROR 2024-10-05 13:10:21,095 views Could not fetch the latest exchange rates: 
Traceback (most recent call last):
  File "C:\Users\achod\OneDrive\Desktop\Archive\brokers\exchange-vista\vista\Lib\site-packages\urllib3\connection.py", line 196, in _new_conn
    sock = connection.create_connection(
           ^^^^^^^^^^^^^^^^^^^^^^^^^^^^^
  File "C:\Users\achod\OneDrive\Desktop\Archive\brokers\exchange-vista\vista\Lib\site-packages\urllib3\util\connection.py", line 60, in create_connection
    for res in socket.getaddrinfo(host, port, family, socket.SOCK_STREAM):
               ^^^^^^^^^^^^^^^^^^^^^^^^^^^^^^^^^^^^^^^^^^^^^^^^^^^^^^^^^^
  File "C:\Users\achod\AppData\Local\Programs\Python\Python312\Lib\socket.py", line 964, in getaddrinfo
    for res in _socket.getaddrinfo(host, port, family, type, proto, flags):
               ^^^^^^^^^^^^^^^^^^^^^^^^^^^^^^^^^^^^^^^^^^^^^^^^^^^^^^^^^^^
socket.gaierror: [Errno 11001] getaddrinfo failed

The above exception was the direct cause of the following exception:

Traceback (most recent call last):
  File "C:\Users\achod\OneDrive\Desktop\Archive\brokers\exchange-vista\vista\Lib\site-packages\urllib3\connectionpool.py", line 789, in urlopen
    response = self._make_request(
               ^^^^^^^^^^^^^^^^^^^
  File "C:\Users\achod\OneDrive\Desktop\Archive\brokers\exchange-vista\vista\Lib\site-packages\urllib3\connectionpool.py", line 490, in _make_request
    raise new_e
  File "C:\Users\achod\OneDrive\Desktop\Archive\brokers\exchange-vista\vista\Lib\site-packages\urllib3\connectionpool.py", line 466, in _make_request
    self._validate_conn(conn)
  File "C:\Users\achod\OneDrive\Desktop\Archive\brokers\exchange-vista\vista\Lib\site-packages\urllib3\connectionpool.py", line 1095, in _validate_conn
    conn.connect()
  File "C:\Users\achod\OneDrive\Desktop\Archive\brokers\exchange-vista\vista\Lib\site-packages\urllib3\connection.py", line 615, in connect
    self.sock = sock = self._new_conn()
                       ^^^^^^^^^^^^^^^^
  File "C:\Users\achod\OneDrive\Desktop\Archive\brokers\exchange-vista\vista\Lib\site-packages\urllib3\connection.py", line 203, in _new_conn
    raise NameResolutionError(self.host, self, e) from e
urllib3.exceptions.NameResolutionError: <urllib3.connection.HTTPSConnection object at 0x000002C8F507B200>: Failed to resolve 'v6.exchangerate-api.com' ([Errno 11001] getaddrinfo failed)

The above exception was the direct cause of the following exception:

Traceback (most recent call last):
  File "C:\Users\achod\OneDrive\Desktop\Archive\brokers\exchange-vista\vista\Lib\site-packages\requests\adapters.py", line 667, in send
    resp = conn.urlopen(
           ^^^^^^^^^^^^^
  File "C:\Users\achod\OneDrive\Desktop\Archive\brokers\exchange-vista\vista\Lib\site-packages\urllib3\connectionpool.py", line 843, in urlopen
    retries = retries.increment(
              ^^^^^^^^^^^^^^^^^^
  File "C:\Users\achod\OneDrive\Desktop\Archive\brokers\exchange-vista\vista\Lib\site-packages\urllib3\util\retry.py", line 519, in increment
    raise MaxRetryError(_pool, url, reason) from reason  # type: ignore[arg-type]
    ^^^^^^^^^^^^^^^^^^^^^^^^^^^^^^^^^^^^^^^^^^^^^^^^^^^
urllib3.exceptions.MaxRetryError: HTTPSConnectionPool(host='v6.exchangerate-api.com', port=443): Max retries exceeded with url: /v6/08e90217d43f932b9acb53f2/latest/GBP (Caused by NameResolutionError("<urllib3.connection.HTTPSConnection object at 0x000002C8F507B200>: Failed to resolve 'v6.exchangerate-api.com' ([Errno 11001] getaddrinfo failed)"))

During handling of the above exception, another exception occurred:

Traceback (most recent call last):
  File "C:\Users\achod\OneDrive\Desktop\Archive\brokers\exchange-vista\exchangevista\app\views.py", line 63, in fetch_exchange_rates
    response = requests.get(url).json()
               ^^^^^^^^^^^^^^^^^
  File "C:\Users\achod\OneDrive\Desktop\Archive\brokers\exchange-vista\vista\Lib\site-packages\requests\api.py", line 73, in get
    return request("get", url, params=params, **kwargs)
           ^^^^^^^^^^^^^^^^^^^^^^^^^^^^^^^^^^^^^^^^^^^^
  File "C:\Users\achod\OneDrive\Desktop\Archive\brokers\exchange-vista\vista\Lib\site-packages\requests\api.py", line 59, in request
    return session.request(method=method, url=url, **kwargs)
           ^^^^^^^^^^^^^^^^^^^^^^^^^^^^^^^^^^^^^^^^^^^^^^^^^
  File "C:\Users\achod\OneDrive\Desktop\Archive\brokers\exchange-vista\vista\Lib\site-packages\requests\sessions.py", line 589, in request
    resp = self.send(prep, **send_kwargs)
           ^^^^^^^^^^^^^^^^^^^^^^^^^^^^^^
  File "C:\Users\achod\OneDrive\Desktop\Archive\brokers\exchange-vista\vista\Lib\site-packages\requests\sessions.py", line 703, in send
    r = adapter.send(request, **kwargs)
        ^^^^^^^^^^^^^^^^^^^^^^^^^^^^^^^
  File "C:\Users\achod\OneDrive\Desktop\Archive\brokers\exchange-vista\vista\Lib\site-packages\requests\adapters.py", line 700, in send
    raise ConnectionError(e, request=request)
requests.exceptions.ConnectionError: HTTPSConnectionPool(host='v6.exchangerate-api.com', port=443): Max retries exceeded with url: /v6/08e90217d43f932b9acb53f2/latest/GBP (Caused by NameResolutionError("<urllib3.connection.HTTPSConnection object at 0x000002C8F507B200>: Failed to resolve 'v6.exchangerate-api.com' ([Errno 11001] getaddrinfo failed)"))
