ERROR 2024-08-17 22:21:07,868 views Failed to send email: [WinError 10060] A connection attempt failed because the connected party did not properly respond after a period of time, or established connection failed because connected host has failed to respond
Traceback (most recent call last):
  File "C:\Users\achod\OneDrive\Desktop\Archive\brokers\exchange-vista\exchangevista\app\views.py", line 1370, in verification
    email.send()
  File "C:\Users\achod\AppData\Local\Programs\Python\Python312\Lib\site-packages\django\core\mail\message.py", line 301, in send
    return self.get_connection(fail_silently).send_messages([self])
           ^^^^^^^^^^^^^^^^^^^^^^^^^^^^^^^^^^^^^^^^^^^^^^^^^^^^^^^^
  File "C:\Users\achod\AppData\Local\Programs\Python\Python312\Lib\site-packages\django\core\mail\backends\smtp.py", line 128, in send_messages
    new_conn_created = self.open()
                       ^^^^^^^^^^^
  File "C:\Users\achod\AppData\Local\Programs\Python\Python312\Lib\site-packages\django\core\mail\backends\smtp.py", line 86, in open
    self.connection = self.connection_class(
                      ^^^^^^^^^^^^^^^^^^^^^^
  File "C:\Users\achod\AppData\Local\Programs\Python\Python312\Lib\smtplib.py", line 1022, in __init__
    SMTP.__init__(self, host, port, local_hostname, timeout,
  File "C:\Users\achod\AppData\Local\Programs\Python\Python312\Lib\smtplib.py", line 255, in __init__
    (code, msg) = self.connect(host, port)
                  ^^^^^^^^^^^^^^^^^^^^^^^^
  File "C:\Users\achod\AppData\Local\Programs\Python\Python312\Lib\smtplib.py", line 341, in connect
    self.sock = self._get_socket(host, port, self.timeout)
                ^^^^^^^^^^^^^^^^^^^^^^^^^^^^^^^^^^^^^^^^^^
  File "C:\Users\achod\AppData\Local\Programs\Python\Python312\Lib\smtplib.py", line 1029, in _get_socket
    new_socket = self.context.wrap_socket(new_socket,
                 ^^^^^^^^^^^^^^^^^^^^^^^^^^^^^^^^^^^^
  File "C:\Users\achod\AppData\Local\Programs\Python\Python312\Lib\ssl.py", line 455, in wrap_socket
    return self.sslsocket_class._create(
           ^^^^^^^^^^^^^^^^^^^^^^^^^^^^^
  File "C:\Users\achod\AppData\Local\Programs\Python\Python312\Lib\ssl.py", line 1042, in _create
    self.do_handshake()
  File "C:\Users\achod\AppData\Local\Programs\Python\Python312\Lib\ssl.py", line 1320, in do_handshake
    self._sslobj.do_handshake()
TimeoutError: [WinError 10060] A connection attempt failed because the connected party did not properly respond after a period of time, or established connection failed because connected host has failed to respond
ERROR 2024-08-18 13:15:40,113 models "Error sending email to emilysirvello@gmail.com", ERROR:not enough values to unpack (expected 2, got 1)
Traceback (most recent call last):
  File "C:\Users\achod\OneDrive\Desktop\Archive\brokers\exchange-vista\exchangevista\app\models.py", line 215, in send_welcome_email
    send_mail(
  File "C:\Users\achod\AppData\Local\Programs\Python\Python312\Lib\site-packages\django\core\mail\__init__.py", line 88, in send_mail
    return mail.send()
           ^^^^^^^^^^^
  File "C:\Users\achod\AppData\Local\Programs\Python\Python312\Lib\site-packages\django\core\mail\message.py", line 301, in send
    return self.get_connection(fail_silently).send_messages([self])
           ^^^^^^^^^^^^^^^^^^^^^^^^^^^^^^^^^^^^^^^^^^^^^^^^^^^^^^^^
  File "C:\Users\achod\AppData\Local\Programs\Python\Python312\Lib\site-packages\django\core\mail\backends\smtp.py", line 136, in send_messages
    sent = self._send(message)
           ^^^^^^^^^^^^^^^^^^^
  File "C:\Users\achod\AppData\Local\Programs\Python\Python312\Lib\site-packages\django\core\mail\backends\smtp.py", line 149, in _send
    from_email = sanitize_address(email_message.from_email, encoding)
                 ^^^^^^^^^^^^^^^^^^^^^^^^^^^^^^^^^^^^^^^^^^^^^^^^^^^^
  File "C:\Users\achod\AppData\Local\Programs\Python\Python312\Lib\site-packages\django\core\mail\message.py", line 99, in sanitize_address
    nm, address = addr
    ^^^^^^^^^^^
ValueError: not enough values to unpack (expected 2, got 1)
ERROR 2024-08-19 16:31:21,750 log Internal Server Error: /app/register/
Traceback (most recent call last):
  File "C:\Users\achod\AppData\Local\Programs\Python\Python312\Lib\site-packages\django\template\base.py", line 502, in parse
    compile_func = self.tags[command]
                   ~~~~~~~~~^^^^^^^^^
KeyError: 'cache'

During handling of the above exception, another exception occurred:

Traceback (most recent call last):
  File "C:\Users\achod\AppData\Local\Programs\Python\Python312\Lib\site-packages\django\core\handlers\exception.py", line 55, in inner
    response = get_response(request)
               ^^^^^^^^^^^^^^^^^^^^^
  File "C:\Users\achod\AppData\Local\Programs\Python\Python312\Lib\site-packages\django\core\handlers\base.py", line 197, in _get_response
    response = wrapped_callback(request, *callback_args, **callback_kwargs)
               ^^^^^^^^^^^^^^^^^^^^^^^^^^^^^^^^^^^^^^^^^^^^^^^^^^^^^^^^^^^^
  File "C:\Users\achod\OneDrive\Desktop\Archive\brokers\exchange-vista\exchangevista\app\views.py", line 343, in signup
    return render(request, 'register.html', {'ref':ref})
           ^^^^^^^^^^^^^^^^^^^^^^^^^^^^^^^^^^^^^^^^^^^^^
  File "C:\Users\achod\AppData\Local\Programs\Python\Python312\Lib\site-packages\django\shortcuts.py", line 25, in render
    content = loader.render_to_string(template_name, context, request, using=using)
              ^^^^^^^^^^^^^^^^^^^^^^^^^^^^^^^^^^^^^^^^^^^^^^^^^^^^^^^^^^^^^^^^^^^^^
  File "C:\Users\achod\AppData\Local\Programs\Python\Python312\Lib\site-packages\django\template\loader.py", line 61, in render_to_string
    template = get_template(template_name, using=using)
               ^^^^^^^^^^^^^^^^^^^^^^^^^^^^^^^^^^^^^^^^
  File "C:\Users\achod\AppData\Local\Programs\Python\Python312\Lib\site-packages\django\template\loader.py", line 15, in get_template
    return engine.get_template(template_name)
           ^^^^^^^^^^^^^^^^^^^^^^^^^^^^^^^^^^
  File "C:\Users\achod\AppData\Local\Programs\Python\Python312\Lib\site-packages\django\template\backends\django.py", line 33, in get_template
    return Template(self.engine.get_template(template_name), self)
                    ^^^^^^^^^^^^^^^^^^^^^^^^^^^^^^^^^^^^^^^
  File "C:\Users\achod\AppData\Local\Programs\Python\Python312\Lib\site-packages\django\template\engine.py", line 177, in get_template
    template, origin = self.find_template(template_name)
                       ^^^^^^^^^^^^^^^^^^^^^^^^^^^^^^^^^
  File "C:\Users\achod\AppData\Local\Programs\Python\Python312\Lib\site-packages\django\template\engine.py", line 159, in find_template
    template = loader.get_template(name, skip=skip)
               ^^^^^^^^^^^^^^^^^^^^^^^^^^^^^^^^^^^^
  File "C:\Users\achod\AppData\Local\Programs\Python\Python312\Lib\site-packages\django\template\loaders\cached.py", line 57, in get_template
    template = super().get_template(template_name, skip)
               ^^^^^^^^^^^^^^^^^^^^^^^^^^^^^^^^^^^^^^^^^
  File "C:\Users\achod\AppData\Local\Programs\Python\Python312\Lib\site-packages\django\template\loaders\base.py", line 28, in get_template
    return Template(
           ^^^^^^^^^
  File "C:\Users\achod\AppData\Local\Programs\Python\Python312\Lib\site-packages\django\template\base.py", line 154, in __init__
    self.nodelist = self.compile_nodelist()
                    ^^^^^^^^^^^^^^^^^^^^^^^
  File "C:\Users\achod\AppData\Local\Programs\Python\Python312\Lib\site-packages\django\template\base.py", line 196, in compile_nodelist
    return parser.parse()
           ^^^^^^^^^^^^^^
  File "C:\Users\achod\AppData\Local\Programs\Python\Python312\Lib\site-packages\django\template\base.py", line 504, in parse
    self.invalid_block_tag(token, command, parse_until)
  File "C:\Users\achod\AppData\Local\Programs\Python\Python312\Lib\site-packages\django\template\base.py", line 565, in invalid_block_tag
    raise self.error(
django.template.exceptions.TemplateSyntaxError: Invalid block tag on line 593: 'cache'. Did you forget to register or load this tag?
ERROR 2024-08-19 16:31:21,774 basehttp "GET /app/register/ HTTP/1.1" 500 170640
ERROR 2024-08-19 16:38:06,548 models Failed to send welcome email to support@exchangevista.com. Error: [Errno 11001] getaddrinfo failed
Traceback (most recent call last):
  File "C:\Users\achod\OneDrive\Desktop\Archive\brokers\exchange-vista\exchangevista\app\models.py", line 56, in send_new_user_email
    send_mail(
  File "C:\Users\achod\AppData\Local\Programs\Python\Python312\Lib\site-packages\django\core\mail\__init__.py", line 88, in send_mail
    return mail.send()
           ^^^^^^^^^^^
  File "C:\Users\achod\AppData\Local\Programs\Python\Python312\Lib\site-packages\django\core\mail\message.py", line 301, in send
    return self.get_connection(fail_silently).send_messages([self])
           ^^^^^^^^^^^^^^^^^^^^^^^^^^^^^^^^^^^^^^^^^^^^^^^^^^^^^^^^
  File "C:\Users\achod\AppData\Local\Programs\Python\Python312\Lib\site-packages\django\core\mail\backends\smtp.py", line 128, in send_messages
    new_conn_created = self.open()
                       ^^^^^^^^^^^
  File "C:\Users\achod\AppData\Local\Programs\Python\Python312\Lib\site-packages\django\core\mail\backends\smtp.py", line 86, in open
    self.connection = self.connection_class(
                      ^^^^^^^^^^^^^^^^^^^^^^
  File "C:\Users\achod\AppData\Local\Programs\Python\Python312\Lib\smtplib.py", line 1022, in __init__
    SMTP.__init__(self, host, port, local_hostname, timeout,
  File "C:\Users\achod\AppData\Local\Programs\Python\Python312\Lib\smtplib.py", line 255, in __init__
    (code, msg) = self.connect(host, port)
                  ^^^^^^^^^^^^^^^^^^^^^^^^
  File "C:\Users\achod\AppData\Local\Programs\Python\Python312\Lib\smtplib.py", line 341, in connect
    self.sock = self._get_socket(host, port, self.timeout)
                ^^^^^^^^^^^^^^^^^^^^^^^^^^^^^^^^^^^^^^^^^^
  File "C:\Users\achod\AppData\Local\Programs\Python\Python312\Lib\smtplib.py", line 1028, in _get_socket
    new_socket = super()._get_socket(host, port, timeout)
                 ^^^^^^^^^^^^^^^^^^^^^^^^^^^^^^^^^^^^^^^^
  File "C:\Users\achod\AppData\Local\Programs\Python\Python312\Lib\smtplib.py", line 312, in _get_socket
    return socket.create_connection((host, port), timeout,
           ^^^^^^^^^^^^^^^^^^^^^^^^^^^^^^^^^^^^^^^^^^^^^^^
  File "C:\Users\achod\AppData\Local\Programs\Python\Python312\Lib\socket.py", line 829, in create_connection
    for res in getaddrinfo(host, port, 0, SOCK_STREAM):
               ^^^^^^^^^^^^^^^^^^^^^^^^^^^^^^^^^^^^^^^
  File "C:\Users\achod\AppData\Local\Programs\Python\Python312\Lib\socket.py", line 964, in getaddrinfo
    for res in _socket.getaddrinfo(host, port, family, type, proto, flags):
               ^^^^^^^^^^^^^^^^^^^^^^^^^^^^^^^^^^^^^^^^^^^^^^^^^^^^^^^^^^^
socket.gaierror: [Errno 11001] getaddrinfo failed
